<?xml version="1.0" encoding="utf-8"?>
<!-- This URDF was automatically created by SolidWorks to URDF Exporter! Originally created by Stephen Brawner (brawner@gmail.com) 
     Commit Version: 1.6.0-1-g15f4949  Build Version: 1.6.7594.29634
     For more information, please see http://wiki.ros.org/sw_urdf_exporter -->
<robot name="cobot_description" xmlns:xacro="http://ros.org/wiki/xacro">
  <xacro:include filename="$(find rm_75_description)/urdf/rm_75.transmission.xacro"/>
  <xacro:include filename="$(find rm_75_description)/urdf/rm_75.gazebo.xacro"/>

  <!-- <xacro:include filename="$(find dh_robotics_ag95_description)/urdf/dh_robotics_ag95_gripper.urdf.xacro" /> -->

  <xacro:include filename="$(find ranger_mini_v2_gazebo)/xacro/ranger_mini_gazebo_b.xacro"/>

  <link
    name="base_footprint">
  </link>

  <link
    name="box">
    <visual>
      <origin
        xyz="-0.365 -0.25 0"
        rpy="0 0 0" />
      <geometry>
        <mesh filename="package://cobot_description/meshes/box.STL" scale="0.001 0.001 0.001"/>
      </geometry>
      <material
        name="">
        <color
          rgba="0.77647 0.77647 0.81961 1" />
      </material>
    </visual>
  </link>

  <joint
    name="box_link_joint"
    type="fixed">
    <origin
      xyz="0 0 0"
      rpy="0 0 0" />
    <parent
      link="base_link" />
    <child
      link="box" />
    <axis
      xyz="0 0 0" />
  </joint>


  <joint
    name="base_link_joint"
    type="fixed">
    <origin
      xyz="0.201 0 0.072"
      rpy="0 0 0" />
    <parent
      link="base_footprint" />
    <child
      link="base_link" />
    <axis
      xyz="0 0 0" />
  </joint>

  <link
    name="arm_base">
    <inertial>
      <origin
        xyz="-0.024179 0.0061525 0.44341"
        rpy="0 0 0" />
      <!-- <mass value="8.0743" /> -->
      <mass value="0.0743" />
      <inertia
        ixx="0.080601"
        ixy="4.9995E-05"
        ixz="0.00052048"
        iyy="0.077325"
        iyz="-2.0984E-05"
        izz="0.024026" />
    </inertial>
    <visual>
      <origin
        xyz="0 0 0"
        rpy="0 0 0" />
      <geometry>
        <mesh
          filename="package://cobot_description/meshes/arm_base.STL" />
      </geometry>
      <material
        name="">
        <color
          rgba="0.69804 0.69804 0.69804 1" />
      </material>
    </visual>
    <collision>
      <origin
        xyz="0 0 0"
        rpy="0 0 0" />
      <geometry>
        <mesh
          filename="package://cobot_description/meshes/arm_base.STL" />
      </geometry>
    </collision>
  </link>
  <joint
    name="arm_base_joint"
    type="fixed">
    <origin
      xyz="-0.101 0 0.16"
      rpy="0 0 3.14"/>
    <parent
      link="base_link" />
    <child
      link="arm_base" />
    <axis
      xyz="0 0 0" />
  </joint>
  <link
    name="Link7">
    <inertial>
      <origin
        xyz="-0.016412 0.00026497 -0.060445"
        rpy="0 0 0" />
      <mass
        value="0.53096" />
      <inertia
        ixx="0.00096525"
        ixy="1.49E-05"
        ixz="-1.7049E-05"
        iyy="0.0018872"
        iyz="1.0632E-06"
        izz="0.0018331" />
    </inertial>
    <visual>
      <origin
        xyz="0 0 0"
        rpy="0 0 0" />
      <geometry>
        <mesh
          filename="package://cobot_description/meshes/Link7.STL" />
      </geometry>
      <material
        name="">
        <color
          rgba="1 1 1 1" />
      </material>
    </visual>
    <!-- <collision>
      <origin
        xyz="0 0 0"
        rpy="0 0 0" />
      <geometry>
        <mesh
          filename="package://cobot_description/meshes/Link7.STL" />
      </geometry>
    </collision> -->
  </link>
  <joint
    name="joint7"
    type="revolute">
    <origin
      xyz="0 0 0.4878"
      rpy="3.1416 0 1.5708" />
    <parent
      link="arm_base" />
    <child
      link="Link7" />
    <axis
      xyz="0 0 -1" />
    <limit
      lower="-1.9"
      upper="1.9"
      effort="300"
      velocity="3.14" />
	  <dynamics damping="50" friction="1"/>
  </joint>
  <link
    name="Link1">
    <inertial>
      <origin
        xyz="-1.79862733952242E-05 -0.0216004812887538 0.0719258896443856"
        rpy="0 0 0" />
      <mass
        value="0.200843839724735" />
      <inertia
        ixx="0.000531136984021332"
        ixy="-4.32776127280478E-07"
        ixz="1.04793272362077E-06"
        iyy="0.000497444611373595"
        iyz="0.000106254355496355"
        izz="0.000282103590137435" />
    </inertial>
    <visual>
      <origin
        xyz="0 0 0"
        rpy="0 0 0" />
      <geometry>
        <mesh
          filename="package://cobot_description/meshes/rm65_meshes/Link1.STL" />
      </geometry>
      <material
        name="">
        <color
          rgba="1 1 1 1" />
      </material>
    </visual>
    <collision>
      <origin
        xyz="0 0 0"
        rpy="0 0 0" />
      <geometry>
        <mesh
          filename="package://cobot_description/meshes/rm65_meshes/Link1.STL" />
      </geometry>
    </collision>
  </link>
  <joint
    name="joint1"
    type="revolute">
    <origin
      xyz="-0.1157 0 -0.059"
      rpy="1.5708 0 -1.5708" />
    <parent
      link="Link7" />
    <child
      link="Link1" />
    <axis
      xyz="0 0 1" />
    <limit
      lower="-3.14"
      upper="3.14"
      effort="300"
      velocity="3.14" />
	  <dynamics damping="50" friction="1"/>
  </joint>
  <link
    name="Link2">
    <inertial>
      <origin
        xyz="0.133181684940056 -4.09216469913973E-05 0.0184216581306229"
        rpy="0 0 0" />
      <mass
        value="0.321307361964397" />
      <inertia
        ixx="0.000440014028766832"
        ixy="5.6579315252598E-07"
        ixz="-0.000654853772254918"
        iyy="0.00298539844077015"
        iyz="1.20748806355071E-07"
        izz="0.00284806640328522" />
    </inertial>
    <visual>
      <origin
        xyz="0 0 0"
        rpy="0 0 0" />
      <geometry>
        <mesh
          filename="package://cobot_description/meshes/rm65_meshes/Link2.STL" />
      </geometry>
      <material
        name="">
        <color
          rgba="1 1 1 1" />
      </material>
    </visual>
    <collision>
      <origin
        xyz="0 0 0"
        rpy="0 0 0" />
      <geometry>
        <mesh
          filename="package://cobot_description/meshes/rm65_meshes/Link2.STL" />
      </geometry>
    </collision>
  </link>
  <joint
    name="joint2"
    type="revolute">
    <origin
      xyz="0 0.016171 0.1012"
      rpy="1.5708 -1.5708 0" />
    <parent
      link="Link1" />
    <child
      link="Link2" />
    <axis
      xyz="0 0 -1" />
    <limit
      lower="-2.26"
      upper="2.26"
      effort="300"
      velocity="3.14" />
	  <dynamics damping="50" friction="1"/>
  </joint>
  <link
    name="Link3">
    <inertial>
      <origin
        xyz="-3.56690328818382E-06 -0.0512866037910138 2.10951876323563E-05"
        rpy="0 0 0" />
      <mass
        value="0.102772515618803" />
      <inertia
        ixx="0.000236471825455939"
        ixy="-2.85439143488268E-09"
        ixz="-4.04883470632046E-10"
        iyy="7.36858171850124E-05"
        iyz="5.2218422744868E-05"
        izz="0.000233873582444284" />
    </inertial>
    <visual>
      <origin
        xyz="0 0 0"
        rpy="0 0 0" />
      <geometry>
        <mesh
          filename="package://cobot_description/meshes/rm65_meshes/Link3.STL" />
      </geometry>
      <material
        name="">
        <color
          rgba="1 1 1 1" />
      </material>
    </visual>
    <collision>
      <origin
        xyz="0 0 0"
        rpy="0 0 0" />
      <geometry>
        <mesh
          filename="package://cobot_description/meshes/rm65_meshes/Link3.STL" />
      </geometry>
    </collision>
  </link>
  <joint
    name="joint3"
    type="revolute">
    <origin
      xyz="0.25576 0 0.0035251"
      rpy="1.1972E-16 1.4979E-28 1.5708" />
    <parent
      link="Link2" />
    <child
      link="Link3" />
    <axis
      xyz="0 0 -1" />
    <limit
      lower="-2.35"
      upper="2.35"
      effort="300"
      velocity="3.14" />
	  <dynamics damping="50" friction="1"/>
  </joint>
  <link
    name="Link4">
    <inertial>
      <origin
        xyz="6.79143687717758E-05 0.0172073813582943 0.0550497562490089"
        rpy="0 0 0" />
      <mass
        value="0.0751534548575527" />
      <inertia
        ixx="0.000114971629184183"
        ixy="1.55043636696422E-08"
        ixz="2.03173541830271E-07"
        iyy="0.000105991655073516"
        iyz="-2.1400189980959E-05"
        izz="5.71243912493456E-05" />
    </inertial>
    <visual>
      <origin
        xyz="0 0 0"
        rpy="0 0 0" />
      <geometry>
        <mesh
          filename="package://cobot_description/meshes/rm65_meshes/Link4.STL" />
      </geometry>
      <material
        name="">
        <color
          rgba="1 1 1 1" />
      </material>
    </visual>
    <collision>
      <origin
        xyz="0 0 0"
        rpy="0 0 0" />
      <geometry>
        <mesh
          filename="package://cobot_description/meshes/rm65_meshes/Link4.STL" />
      </geometry>
    </collision>
  </link>
  <joint
    name="joint4"
    type="revolute">
    <origin
      xyz="0 -0.128 0.013234"
      rpy="1.5708 0 1.2512E-12" />
    <parent
      link="Link3" />
    <child
      link="Link4" />
    <axis
      xyz="0 0 1" />
    <limit
      lower="-3.14"
      upper="3.14"
      effort="300"
      velocity="3.14" />
	  <dynamics damping="50" friction="1"/>
  </joint>
  <link
    name="Link5">
    <inertial>
      <origin
        xyz="-2.14593281051834E-06 -0.049119542458982 0.00236936437088902"
        rpy="0 0 0" />
      <mass
        value="0.0716575200885179" />
      <inertia
        ixx="0.000135381803103201"
        ixy="2.17516760135376E-09"
        ixz="8.55618321137308E-10"
        iyy="4.67751191123099E-05"
        iyz="2.92366122866633E-05"
        izz="0.000132066640473067" />
    </inertial>
    <visual>
      <origin
        xyz="0 0 0"
        rpy="0 0 0" />
      <geometry>
        <mesh
          filename="package://cobot_description/meshes/rm65_meshes/Link5.STL" />
      </geometry>
      <material
        name="">
        <color
          rgba="1 1 1 1" />
      </material>
    </visual>
    <collision>
      <origin
        xyz="0 0 0"
        rpy="0 0 0" />
      <geometry>
        <mesh
          filename="package://cobot_description/meshes/rm65_meshes/Link5.STL" />
      </geometry>
    </collision>
  </link>
  <joint
    name="joint5"
    type="revolute">
    <origin
      xyz="0 -0.0121 0.0815"
      rpy="-1.5708 2.359E-12 5.6484E-28" />
    <parent
      link="Link4" />
    <child
      link="Link5" />
    <axis
      xyz="0 0 -1" />
    <limit
      lower="-2.182"
      upper="2.182"
      effort="300"
      velocity="3.14" />
	  <dynamics damping="50" friction="1"/>
  </joint>
  <link
    name="Link6">
    <inertial>
      <origin
        xyz="0.000610923552198394 0.000226239439845178 0.0217158471531674"
        rpy="0 0 0" />
      <mass
        value="0.0321480840686874" />
      <inertia
        ixx="1.19996413785174E-05"
        ixy="-2.82372207081771E-08"
        ixz="9.42210764600823E-08"
        iyy="1.15507239688493E-05"
        iyz="-4.23625640293711E-08"
        izz="1.77260433647625E-05" />
    </inertial>
    <visual>
      <origin
        xyz="0 0 0"
        rpy="0 0 0" />
      <geometry>
        <mesh
          filename="package://cobot_description/meshes/rm65_meshes/Link6.STL" />
      </geometry>
      <material
        name="">
        <color
          rgba="1 1 1 1" />
      </material>
    </visual>
    <collision>
      <origin
        xyz="0 0 0"
        rpy="0 0 0" />
      <geometry>
        <mesh
          filename="package://cobot_description/meshes/rm65_meshes/Link6.STL" />
      </geometry>
    </collision>
  </link>
  <joint
    name="joint6"
    type="revolute">
    <origin
      xyz="0 -0.115 0.012437"
      rpy="1.5708 0 -2.359E-12" />
    <parent
      link="Link5" />
    <child
      link="Link6" />
    <axis
      xyz="0 0 1" />
    <limit
      lower="-3.14"
      upper="3.14"
      effort="300"
      velocity="1" />
	  <dynamics damping="50" friction="1"/>
  </joint>
  <link
    name="tool_link">
    <inertial>
      <origin
        xyz="-1.4586E-14 1.6875E-14 0.0086479"
        rpy="0 0 0" />
      <mass
        value="0.88542" />
      <inertia
        ixx="0.00049603"
        ixy="1.3553E-20"
        ixz="-6.8101E-19"
        iyy="0.00049603"
        iyz="4.0658E-19"
        izz="0.00097955" />
    </inertial>
    <visual>
      <origin
        xyz="0 0 0"
        rpy="0 0 0" />
      <geometry>
        <mesh
          filename="package://cobot_description/meshes/tool_link.STL" />
      </geometry>
      <material
        name="">
        <color
          rgba="0.77647 0.77647 0.81961 1" />
      </material>
    </visual>
    <collision>
      <origin
        xyz="0 0 0"
        rpy="0 0 0" />
      <geometry>
        <mesh
          filename="package://cobot_description/meshes/tool_link.STL" />
      </geometry>
    </collision>
  </link>
  <joint name="tool_joint" type="fixed">
    <origin xyz="0 0 0.03103" rpy="0 0 -2.618" />
    <parent link="Link6" />
    <child link="tool_link" />
  </joint>
  <!-- <joint
    name="hand_joint"
    type="fixed">
    <origin
      xyz="0 0 0.018"
      rpy="0 0 2.3761" />
    <parent
      link="tool_link" />
    <child
      link="dh_robotics_ag95_base_link" />
  </joint> -->
    <xacro:dh_robotics_ag95_gripper prefix="" parent="tool_link" >
        <origin xyz="0 0 0.04" rpy="0 0 0"/>
    </xacro:dh_robotics_ag95_gripper>
  <link
    name="hand_camera">
    <inertial>
      <origin
        xyz="0.0009804 0.025556 -0.036977"
        rpy="0 0 0" />
      <mass
        value="0.067926" />
      <inertia
        ixx="3.7811E-05"
        ixy="2.2861E-18"
        ixz="2.2446E-19"
        iyy="9.4061E-05"
        iyz="6.1172E-06"
        izz="0.00012345" />
    </inertial>
    <visual>
      <origin
        xyz="0 0 0"
        rpy="0 0 0" />
      <geometry>
        <mesh
          filename="package://cobot_description/meshes/hand_camera.STL" />
      </geometry>
      <material
        name="">
        <color
          rgba="1 1 1 1" />
      </material>
    </visual>
    <collision>
      <origin
        xyz="0 0 0"
        rpy="0 0 0" />
      <geometry>
        <mesh
          filename="package://cobot_description/meshes/hand_camera.STL" />
      </geometry>
    </collision>
  </link>
  <joint
    name="hand_camera_joint"
    type="fixed">
    <origin
      xyz="-0.049074 0.048515 0.06645"
      rpy="0.066568 0 -2.3363" />
    <parent
      link="tool_link" />
    <child
      link="hand_camera" />
    <axis
      xyz="0 0 0" />
  </joint>
  <link
    name="neck_lidar">
    <inertial>
      <origin
        xyz="7.4985E-05 4.6845E-07 4.6452E-05"
        rpy="0 0 0" />
      <mass
        value="0.05" />
      <inertia
        ixx="305.18"
        ixy="-1.6368E-07"
        ixz="-1.1909E-05"
        iyy="305.18"
        iyz="-5.2042E-08"
        izz="583.7" />
    </inertial>
    <visual>
      <origin
        xyz="0 0 0"
        rpy="0 0 0" />
      <geometry>
        <mesh
          filename="package://cobot_description/meshes/neck_lidar.STL" />
      </geometry>
      <material
        name="">
        <color
          rgba="0.24706 0.96471 1 1" />
      </material>
    </visual>
    <collision>
      <origin
        xyz="0 0 0"
        rpy="0 0 0" />
      <geometry>
        <mesh
          filename="package://cobot_description/meshes/neck_lidar.STL" />
      </geometry>
    </collision>
  </link>
  <joint
    name="neck_lidar_joint"
    type="fixed">
    <!-- <origin
      xyz="0.041909 0 1.1614"
      rpy="0 0.5236 0" /> -->
    <origin
      xyz="-0.22 0 1.07"
      rpy="0 0.5236 3.14" />
    <parent
      link="base_link" />
    <child
      link="neck_lidar" />
    <axis
      xyz="0 0 0" />
  </joint>

  <link
    name="head_Link">
    <inertial>
      <origin
        xyz="-0.013341 -0.0030001 0.14378"
        rpy="0 0 0" />
      <mass
        value="0.10888" />
      <inertia
        ixx="0.00015548"
        ixy="5.612E-11"
        ixz="7.7393E-06"
        iyy="6.2021E-05"
        iyz="-3.4676E-10"
        izz="0.00016861" />
    </inertial>
    <visual>
      <origin
        xyz="0 0 0"
        rpy="0 0 0" />
      <geometry>
        <mesh
          filename="package://cobot_description/meshes/head_Link.STL" />
      </geometry>
      <material
        name="">
        <color
          rgba="1 1 1 1" />
      </material>
    </visual>
    <collision>
      <origin
        xyz="0 0 0"
        rpy="0 0 0" />
      <geometry>
        <mesh
          filename="package://cobot_description/meshes/head_Link.STL" />
      </geometry>
    </collision>
  </link>
  <joint
    name="head_joint"
    type="fixed">
    <origin
      xyz="-0.10013 0 1.1628"
      rpy="0 0 3.1416" />
    <parent
      link="base_link" />
    <child
      link="head_Link" />
    <axis
      xyz="0 0 0" />
  </joint>
  <link
    name="display_Link">
    <collision>
      <origin
        xyz="0 0 0"
        rpy="0 0 0" />
      <geometry>
        <box size="0.03 0.3 0.2" />
      </geometry>
    </collision>
  </link>
  <joint
    name="display_joint"
    type="fixed">
    <origin
      xyz="0.15 0 -0.1"
      rpy="0 0 0" />
    <parent
      link="head_Link" />
    <child
      link="display_Link" />
    <axis
      xyz="0 0 0" />
  </joint>
  <link
    name="head_camera">
    <inertial>
      <origin
        xyz="0.027537 -0.14823 -1.1256"
        rpy="0 0 0" />
      <mass
        value="0.092" />
      <inertia
        ixx="16.389"
        ixy="0.28606"
        ixz="-0.57062"
        iyy="13.534"
        iyz="-2.6339"
        izz="7.1915" />
    </inertial>
    <visual>
      <origin
        xyz="0 0 0"
        rpy="0 0 0" />
      <geometry>
        <mesh
          filename="package://cobot_description/meshes/head_camera.STL" />
      </geometry>
      <material
        name="">
        <color
          rgba="1 1 1 1" />
      </material>
    </visual>
    <collision>
      <origin
        xyz="0 0 0"
        rpy="0 0 0" />
      <geometry>
        <mesh
          filename="package://cobot_description/meshes/head_camera.STL" />
      </geometry>
    </collision>
  </link>
  <joint
    name="head_camera_joint"
    type="fixed">
    <origin
      xyz="-0.033687 -0.0039804 0.18195"
      rpy="0.066568 0 1.5708" />
    <parent
      link="head_Link" />
    <child
      link="head_camera" />
    <axis
      xyz="0 0 0" />
  </joint>

    <!-- Transmissions for ROS Control -->
    <xacro:macro name="transmission_block" params="joint_name">
        <transmission name="tran1">
            <type>transmission_interface/SimpleTransmission</type>
            <joint name="${joint_name}">
                <hardwareInterface>hardware_interface/PositionJointInterface</hardwareInterface>
            </joint>
            <actuator name="motor1">
                <hardwareInterface>hardware_interface/PositionJointInterface</hardwareInterface>
                <mechanicalReduction>1</mechanicalReduction>
            </actuator>
        </transmission>
    </xacro:macro>
    
    <xacro:transmission_block joint_name="joint1"/>
    <xacro:transmission_block joint_name="joint2"/>
    <xacro:transmission_block joint_name="joint3"/>
    <xacro:transmission_block joint_name="joint4"/>
    <xacro:transmission_block joint_name="joint5"/>
    <xacro:transmission_block joint_name="joint6"/>
    <xacro:transmission_block joint_name="joint7"/>

    <!-- ros_control plugin -->
    <!-- <gazebo>
        <plugin name="gazebo_ros_control" filename="libgazebo_ros_control.so">
            <robotNamespace>/arm</robotNamespace>
            <robotSimType>gazebo_ros_control/DefaultRobotHWSim</robotSimType>
            <legacyModeNS>true</legacyModeNS>
        </plugin>
    </gazebo> -->

</robot>